Workbook

Sheet Dashboard
A1: Ancient History Reconstruction Workbook v3
A3: Purpose | B3: Research inventory for reconstructing ancient history from archaeology, texts, inscriptions, oral traditions, and object corpora. Focus is BCE through 1 AD, with later witnesses flagged separately when they preserve older traditions or are commonly cited by alternative-history writers.
A4: How to use | B4: Filter Master_Inventory by Region, Scope_Flag, Theme, Research_Priority, or Alt_History_Citation_Level. Use Suggested_Search_Term inside the linked portal. Treat Evidence_Notes as your guardrail between artifact/text facts and speculative interpretation.
A5: Date generated | B5: 2026-04-07
A7: Key totals | C7: New in v3 | D7: Value | E7: Theme starter paths
A8: Metric | B8: Value | C8: Character parallels rows | D8: 50 | E8: Theme | F8: Start with | G8: Why
A9: Total records | B9: =COUNTA(Master_Inventory!A:A)-1 | C9: Master inventory rows | D9: =COUNTA(Master_Inventory!A:A)-1 | E9: Creation | F9: Genesis; Enuma Elish; Eridu Genesis; Pyramid Texts; Rigveda creation hymns; Theogony; Shan Hai Jing; Popol Vuh (later witness) | G9: Gives you competing world-beginning models and recurring chaos-water motifs.
A10: Later witness / post-1 AD | B10: =COUNTIF(Master_Inventory!B:B,"Later_witness_or_post_1AD_relevance") | C10: Records with enriched source-search URLs | D10: =COUNTA(Master_Inventory!AJ:AJ)-1 | E10: Flood / catastrophe | F10: Atrahasis; Gilgamesh XI; Ziusudra; Genesis 6-9; Manu flood; Yu the Great flood traditions; Viracocha traditions (later witness) | G10: Fastest path for cross-cultural comparison and character-merging work.
A11: High alt-history citation | B11: =COUNTIF(Master_Inventory!Q:Q,"High") | C11: Text / manuscript / inscription rows | D11: =COUNTIF(Master_Inventory!I:I,"Text")+COUNTIF(Master_Inventory!I:I,"Text tradition")+COUNTIF(Master_Inventory!I:I,"Inscription")+COUNTIF(Master_Inventory!I:I,"Inscription corpus")+COUNTIF(Master_Inventory!I:I,"Tablet corpus")+COUNTIF(Master_Inventory!I:I,"Manuscript corpus") | E11: Civilizer gods / culture heroes | F11: Enki and the World Order; Oannes/Apkallu material; Quetzalcoatl traditions; Viracocha traditions; Osiris and Ptah material; Yu the Great | G11: Tracks post-catastrophe order, teaching, and sacred technology.
E12: Astronomy / calendars | F12: MUL.APIN; Enuma Anu Enlil; Dendera corpus; Mawangdui maps; Maya codices (later witness); Antikythera Mechanism; Stonehenge/Newgrange/Nabta Playa | G12: Maps the strongest evidence for formal sky knowledge.
E13: Kingship / king lists | F13: Sumerian King List; Abydos King List; Turin Canon; Behistun; Ashokan Edicts; Mesha Stele; Oracle bones; Shujing | G13: Lets you separate historiography from myth while keeping both in play.
A14: Records by region
A15: Region | B15: Records | C15: Criticals
A16: Prehistory / Neolithic | B16: =COUNTIF(Master_Inventory!C:C,"Prehistory / Neolithic") | C16: =COUNTIFS(Master_Inventory!C:C,"Prehistory / Neolithic",Master_Inventory!AG:AG,"Critical") | E16: Legend
A17: Mesopotamia | B17: =COUNTIF(Master_Inventory!C:C,"Mesopotamia") | C17: =COUNTIFS(Master_Inventory!C:C,"Mesopotamia",Master_Inventory!AG:AG,"Critical") | E17: Scope_Flag = BCE_to_1AD | F17: Core dataset inside requested timeline.
A18: Egypt | B18: =COUNTIF(Master_Inventory!C:C,"Egypt") | C18: =COUNTIFS(Master_Inventory!C:C,"Egypt",Master_Inventory!AG:AG,"Critical") | E18: Scope_Flag = Later_witness_or_post_1AD_relevance | F18: Later manuscript/site/oral witness kept because it preserves older tradition or is central in alternative-history discourse.
A19: Levant / Israel / Phoenicia | B19: =COUNTIF(Master_Inventory!C:C,"Levant / Israel / Phoenicia") | C19: =COUNTIFS(Master_Inventory!C:C,"Levant / Israel / Phoenicia",Master_Inventory!AG:AG,"Critical") | E19: Translation_Available = No | F19: Usually undeciphered script or non-text object.
A20: Iran / Central Asia | B20: =COUNTIF(Master_Inventory!C:C,"Iran / Central Asia") | C20: =COUNTIFS(Master_Inventory!C:C,"Iran / Central Asia",Master_Inventory!AG:AG,"Critical") | E20: Alt_History_Citation_Level = High | F20: Commonly cited by Hancock, ancient-astronaut writers, megalithic/lost-civilization media, or adjacent channels.
A21: South Asia | B21: =COUNTIF(Master_Inventory!C:C,"South Asia") | C21: =COUNTIFS(Master_Inventory!C:C,"South Asia",Master_Inventory!AG:AG,"Critical")
A22: China | B22: =COUNTIF(Master_Inventory!C:C,"China") | C22: =COUNTIFS(Master_Inventory!C:C,"China",Master_Inventory!AG:AG,"Critical")
A23: Japan / Korea | B23: =COUNTIF(Master_Inventory!C:C,"Japan / Korea") | C23: =COUNTIFS(Master_Inventory!C:C,"Japan / Korea",Master_Inventory!AG:AG,"Critical")
A24: Aegean / Greece / Italy | B24: =COUNTIF(Master_Inventory!C:C,"Aegean / Greece / Italy") | C24: =COUNTIFS(Master_Inventory!C:C,"Aegean / Greece / Italy",Master_Inventory!AG:AG,"Critical")
A25: Northern / Celtic Europe | B25: =COUNTIF(Master_Inventory!C:C,"Northern / Celtic Europe") | C25: =COUNTIFS(Master_Inventory!C:C,"Northern / Celtic Europe",Master_Inventory!AG:AG,"Critical")
A26: Africa (outside Egypt) | B26: =COUNTIF(Master_Inventory!C:C,"Africa (outside Egypt)") | C26: =COUNTIFS(Master_Inventory!C:C,"Africa (outside Egypt)",Master_Inventory!AG:AG,"Critical")
A27: Mesoamerica | B27: =COUNTIF(Master_Inventory!C:C,"Mesoamerica") | C27: =COUNTIFS(Master_Inventory!C:C,"Mesoamerica",Master_Inventory!AG:AG,"Critical")
A28: Andes / South America | B28: =COUNTIF(Master_Inventory!C:C,"Andes / South America") | C28: =COUNTIFS(Master_Inventory!C:C,"Andes / South America",Master_Inventory!AG:AG,"Critical")
A29: North America / Oceania | B29: =COUNTIF(Master_Inventory!C:C,"North America / Oceania") | C29: =COUNTIFS(Master_Inventory!C:C,"North America / Oceania",Master_Inventory!AG:AG,"Critical")

Sheet Master_Inventory
A1: Record_ID | B1: Scope_Flag | C1: Region | D1: Culture_Tradition | E1: Start_Year_Signed | F1: End_Year_Signed | G1: Date_Label | H1: Item_Name | I1: Item_Type | J1: Preservation_Mode | K1: Theme_1 | L1: Theme_2 | M1: Modern_Location | N1: Ancient_Location | O1: Factual_Description | P1: Why_It_Matters | Q1: Alt_History_Citation_Level | R1: Translation_Available | S1: Image_Access | T1: Primary_Portal | U1: Primary_URL | V1: Translation_Portal | W1: Translation_URL | X1: Image_Object_Portal | Y1: Image_Object_URL | Z1: Context_Portal | AA1: Context_URL | AB1: Map_Portal | AC1: Map_URL | AD1: Suggested_Search_Term | AE1: Evidence_Notes | AF1: Cross_Cultural_Links | AG1: Research_Priority | AH1: Opportunity_Level | AI1: User_Notes | AJ1: Primary_Search_URL | AK1: Translation_Search_URL | AL1: Image_Search_URL | AM1: Context_Search_URL | AN1: Map_Search_URL | AO1: Recommended_Source_Workflow | AP1: Source_Directness_Note
A2: 1 | B2: BCE_to_1AD | C2: Prehistory / Neolithic | D2: Prehistory and Neolithic traditions | E2: -9600 | F2: -8200 | G2: c. 9600 BCE to 8200 BCE | H2: Gobekli Tepe | I2: Site | J2: Archaeology | K2: Megaliths | L2: Ritual | M2: Turkey | N2: Upper Mesopotamia | O2: Monumental Pre-Pottery Neolithic ritual complex with carved T-pillars and enclosures. | P2: Earliest large ritual architecture commonly cited in deep-prehistory narratives. | Q2: High | R2: Not applicable | S2: High | T2: UNESCO | U2: https://whc.unesco.org/ | V2: UNESCO | W2: https://whc.unesco.org/ | X2: Smithsonian Open Access | Y2: https://www.si.edu/openaccess | Z2: UNESCO | AA2: https://whc.unesco.org/ | AB2: UNESCO | AC2: https://whc.unesco.org/ | AD2: Gobekli Tepe UNESCO | AE2: Use excavation reports for layout and pillar phases. | AF2: Monumentality; origins of ritual; sky-symbol debates | AG2: Critical | AH2: High | AJ2: https://whc.unesco.org/en/search/?searchterm=Gobekli+Tepe+UNESCO | AK2: https://whc.unesco.org/en/search/?searchterm=Gobekli+Tepe+UNESCO | AL2: https://www.si.edu/collection/search?edan_q=Gobekli+Tepe+UNESCO | AM2: https://whc.unesco.org/en/search/?searchterm=Gobekli+Tepe+UNESCO | AN2: https://whc.unesco.org/en/search/?searchterm=Gobekli+Tepe+UNESCO | AO2: 1) Fact base: UNESCO. 2) Translation/text: UNESCO. 3) Images/objects: Smithsonian Open Access. 4) Context/explanation: UNESCO. 5) Geography/maps: UNESCO. Use Suggested_Search_Term inside each portal. | AP2: Mixed: direct portal homepages plus search-result URLs where the portal exposes a public search endpoint.
A3: 2 | B3: BCE_to_1AD | C3: Prehistory / Neolithic | D3: Prehistory and Neolithic traditions | E3: -9500 | F3: -8000 | G3: c. 9500 BCE to 8000 BCE | H3: Karahan Tepe | I3: Site | J3: Archaeology | K3: Megaliths | L3: Ritual | M3: Turkey | N3: Tas Tepeler region | O3: Large Pre-Pottery Neolithic site with carved pillars, human imagery, and rock-cut features. | P3: Key comparative site to avoid treating Gobekli Tepe as unique in isolation. | Q3: High | R3: Not applicable | S3: Medium | T3: UNESCO | U3: https://whc.unesco.org/ | V3: UNESCO | W3: https://whc.unesco.org/ | X3: Smithsonian Open Access | Y3: https://www.si.edu/openaccess | Z3: UNESCO | AA3: https://whc.unesco.org/ | AB3: UNESCO | AC3: https://whc.unesco.org/ | AD3: Karahan Tepe Tas Tepeler | AE3: Data set still expanding; check latest excavation summaries. | AF3: Gobekli cluster; ritual networks | AG3: Critical | AH3: High | AJ3: https://whc.unesco.org/en/search/?searchterm=Karahan+Tepe+Tas+Tepeler | AK3: https://whc.unesco.org/en/search/?searchterm=Karahan+Tepe+Tas+Tepeler | AL3: https://www.si.edu/collection/search?edan_q=Karahan+Tepe+Tas+Tepeler | AM3: https://whc.unesco.org/en/search/?searchterm=Karahan+Tepe+Tas+Tepeler | AN3: https://whc.unesco.org/en/search/?searchterm=Karahan+Tepe+Tas+Tepeler | AO3: 1) Fact base: UNESCO. 2) Translation/text: UNESCO. 3) Images/objects: Smithsonian Open Access. 4) Context/explanation: UNESCO. 5) Geography/maps: UNESCO. Use Suggested_Search_Term inside each portal. | AP3: Mixed: direct portal homepages plus search-result URLs where the portal exposes a public search endpoint.
A4: 3 | B4: BCE_to_1AD | C4: Prehistory / Neolithic | D4: Prehistory and Neolithic traditions | E4: -8500 | F4: -7900 | G4: c. 8500 BCE to 7900 BCE | H4: Nevali Cori | I4: Site | J4: Archaeology | K4: Megaliths | L4: Settlement | M4: Turkey | N4: Upper Euphrates | O4: Early Neolithic settlement with cult building and T-shaped pillars predating some later sites. | P4: Shows that carved pillar traditions existed across a wider landscape. | Q4: Medium | R4: Not applicable | S4: Medium | T4: UNESCO | U4: https://whc.unesco.org/ | V4: UNESCO | W4: https://whc.unesco.org/ | X4: Smithsonian Open Access | Y4: https://www.si.edu/openaccess | Z4: UNESCO | AA4: https://whc.unesco.org/ | AB4: UNESCO | AC4: https://whc.unesco.org/ | AD4: Nevali Cori excavation | AE4: Mostly known through excavation publications and museum context. | AF4: Gobekli cluster; early cult buildings | AG4: High | AH4: Medium | AJ4: https://whc.unesco.org/en/search/?searchterm=Nevali+Cori+excavation | AK4: https://whc.unesco.org/en/search/?searchterm=Nevali+Cori+excavation | AL4: https://www.si.edu/collection/search?edan_q=Nevali+Cori+excavation | AM4: https://whc.unesco.org/en/search/?searchterm=Nevali+Cori+excavation | AN4: https://whc.unesco.org/en/search/?searchterm=Nevali+Cori+excavation | AO4: 1) Fact base: UNESCO. 2) Translation/text: UNESCO. 3) Images/objects: Smithsonian Open Access. 4) Context/explanation: UNESCO. 5) Geography/maps: UNESCO. Use Suggested_Search_Term inside each portal. | AP4: Mixed: direct portal homepages plus search-result URLs where the portal exposes a public search endpoint.
A5: 4 | B5: BCE_to_1AD | C5: Prehistory / Neolithic | D5: Prehistory and Neolithic traditions | E5: -7400 | F5: -6200 | G5: c. 7400 BCE to 6200 BCE | H5: Catalhoyuk | I5: Site | J5: Archaeology | K5: Settlement | L5: Ritual | M5: Turkey | N5: Central Anatolia | O5: Dense Neolithic tell settlement with wall paintings, burials under houses, and symbolic installations. | P5: Excellent bridge between early village life, ritual practice, and symbolic iconography. | Q5: Medium | R5: Not applicable | S5: High | T5: UNESCO | U5: https://whc.unesco.org/ | V5: UNESCO | W5: https://whc.unesco.org/ | X5: Smithsonian Open Access | Y5: https://www.si.edu/openaccess | Z5: UNESCO | AA5: https://whc.unesco.org/ | AB5: UNESCO | AC5: https://whc.unesco.org/ | AD5: Catalhoyuk Research Project | AE5: Use excavation archive rather than older goddess-heavy speculation alone. | AF5: House cults; symbolic animals; ancestry | AG5: Critical | AH5: High | AJ5: https://whc.unesco.org/en/search/?searchterm=Catalhoyuk+Research+Project | AK5: https://whc.unesco.org/en/search/?searchterm=Catalhoyuk+Research+Project | AL5: https://www.si.edu/collection/search?edan_q=Catalhoyuk+Research+Project | AM5: https://whc.unesco.org/en/search/?searchterm=Catalhoyuk+Research+Project | AN5: https://whc.unesco.org/en/search/?searchterm=Catalhoyuk+Research+Project | AO5: 1) Fact base: UNESCO. 2) Translation/text: UNESCO. 3) Images/objects: Smithsonian Open Access. 4) Context/explanation: UNESCO. 5) Geography/maps: UNESCO. Use Suggested_Search_Term inside each portal. | AP5: Mixed: direct portal homepages plus search-result URLs where the portal exposes a public search endpoint.
A6: 5 | B6: BCE_to_1AD | C6: Prehistory / Neolithic | D6: Prehistory and Neolithic traditions | E6: -9000 | F6: -7000 | G6: c. 9000 BCE to 7000 BCE | H6: Jericho / Tell es-Sultan | I6: Site | J6: Archaeology | K6: Settlement | L6: Fortification | M6: Palestine | N6: Jordan Valley | O6: One of the earliest large sedentary settlements with tower and wall phases. | P6: Important for early urbanism and for later biblical geography overlap. | Q6: Medium | R6: Not applicable | S6: Medium | T6: UNESCO | U6: https://whc.unesco.org/ | V6: UNESCO | W6: https://whc.unesco.org/ | X6: Smithsonian Open Access | Y6: https://www.si.edu/openaccess | Z6: UNESCO | AA6: https://whc.unesco.org/ | AB6: UNESCO | AC6: https://whc.unesco.org/ | AD6: Jericho Tell es-Sultan UNESCO | AE6: Chronology depends on phase; cite excavated levels. | AF6: Origins of settlement; Levantine memory | AG6: High | AH6: Medium | AJ6: https://whc.unesco.org/en/search/?searchterm=Jericho+Tell+es-Sultan+UNESCO | AK6: https://whc.unesco.org/en/search/?searchterm=Jericho+Tell+es-Sultan+UNESCO | AL6: https://www.si.edu/collection/search?edan_q=Jericho+Tell+es-Sultan+UNESCO | AM6: https://whc.unesco.org/en/search/?searchterm=Jericho+Tell+es-Sultan+UNESCO | AN6: https://whc.unesco.org/en/search/?searchterm=Jericho+Tell+es-Sultan+UNESCO | AO6: 1) Fact base: UNESCO. 2) Translation/text: UNESCO. 3) Images/objects: Smithsonian Open Access. 4) Context/explanation: UNESCO. 5) Geography/maps: UNESCO. Use Suggested_Search_Term inside each portal. | AP6: Mixed: direct portal homepages plus search-result URLs where the portal exposes a public search endpoint.
A7: 6 | B7: BCE_to_1AD | C7: Prehistory / Neolithic | D7: Prehistory and Neolithic traditions | E7: -7200 | F7: -6500 | G7: c. 7200 BCE to 6500 BCE | H7: Ain Ghazal | I7: Site | J7: Archaeology | K7: Settlement | L7: Ritual | M7: Jordan | N7: Levant | O7: Neolithic settlement known for plaster statues and large-scale community occupation. | P7: Vital for studying ancestor imagery and ritualized human representation. | Q7: Medium | R7: Not applicable | S7: High | T7: UNESCO | U7: https://whc.unesco.org/ | V7: UNESCO | W7: https://whc.unesco.org/ | X7: Smithsonian Open Access | Y7: https://www.si.edu/openaccess | Z7: UNESCO | AA7: https://whc.unesco.org/ | AB7: UNESCO | AC7: https://whc.unesco.org/ | AD7: Ain Ghazal plaster statues | AE7: Statues are often decontextualized online; keep excavation context attached. | AF7: Ancestor cult; image traditions | AG7: High | AH7: Medium | AJ7: https://whc.unesco.org/en/search/?searchterm=Ain+Ghazal+plaster+statues | AK7: https://whc.unesco.org/en/search/?searchterm=Ain+Ghazal+plaster+statues | AL7: https://www.si.edu/collection/search?edan_q=Ain+Ghazal+plaster+statues | AM7: https://whc.unesco.org/en/search/?searchterm=Ain+Ghazal+plaster+statues | AN7: https://whc.unesco.org/en/search/?searchterm=Ain+Ghazal+plaster+statues | AO7: 1) Fact base: UNESCO. 2) Translation/text: UNESCO. 3) Images/objects: Smithsonian Open Access. 4) Context/explanation: UNESCO. 5) Geography/maps: UNESCO. Use Suggested_Search_Term inside each portal. | AP7: Mixed: direct portal homepages plus search-result URLs where the portal exposes a public search endpoint.
A8: 7 | B8: BCE_to_1AD | C8: Prehistory / Neolithic | D8: Prehistory and Neolithic traditions | E8: -7000 | F8: -4000 | G8: c. 7000 BCE to 4000 BCE | H8: Nabta Playa | I8: Site | J8: Archaeology | K8: Ritual | L8: Astronomy | M8: Egypt | N8: Nubian Desert | O8: Desert ceremonial and pastoral landscape with stone alignments and burials. | P8: Frequently cited in archaeoastronomy and pre-Egypt complexity discussions. | Q8: High | R8: Not applicable | S8: Medium | T8: UNESCO | U8: https://whc.unesco.org/ | V8: UNESCO | W8: https://whc.unesco.org/ | X8: Smithsonian Open Access | Y8: https://www.si.edu/openaccess | Z8: UNESCO | AA8: https://whc.unesco.org/ | AB8: UNESCO | AC8: https://whc.unesco.org/ | AD8: Nabta Playa megaliths | AE8: Astronomical claims vary; keep to excavated features first. | AF8: Sky knowledge; desert ritual | AG8: High | AH8: Medium | AJ8: https://whc.unesco.org/en/search/?searchterm=Nabta+Playa+megaliths | AK8: https://whc.unesco.org/en/search/?searchterm=Nabta+Playa+megaliths | AL8: https://www.si.edu/collection/search?edan_q=Nabta+Playa+megaliths | AM8: https://whc.unesco.org/en/search/?searchterm=Nabta+Playa+megaliths | AN8: https://whc.unesco.org/en/search/?searchterm=Nabta+Playa+megaliths | AO8: 1) Fact base: UNESCO. 2) Translation/text: UNESCO. 3) Images/objects: Smithsonian Open Access. 4) Context/explanation: UNESCO. 5) Geography/maps: UNESCO. Use Suggested_Search_Term inside each portal. | AP8: Mixed: direct portal homepages plus search-result URLs where the portal exposes a public search endpoint.
A9: 8 | B9: BCE_to_1AD | C9: Prehistory / Neolithic | D9: Prehistory and Neolithic traditions | E9: -3600 | F9: -2500 | G9: c. 3600 BCE to 2500 BCE | H9: Ggantija Temples | I9: Site | J9: Archaeology | K9: Megaliths | L9: Ritual | M9: Malta | N9: Gozo | O9: Megalithic temple complex built in the Maltese island tradition. | P9: Shows complex stone ritual architecture outside the Near East. | Q9: Medium | R9: Not applicable | S9: High | T9: UNESCO | U9: https://whc.unesco.org/ | V9: UNESCO | W9: https://whc.unesco.org/ | X9: Smithsonian Open Access | Y9: https://www.si.edu/openaccess | Z9: UNESCO | AA9: https://whc.unesco.org/ | AB9: UNESCO | AC9: https://whc.unesco.org/ | AD9: Ggantija UNESCO | AE9: Use temple sequence and island context together. | AF9: Temple architecture; island cults | AG9: Medium | AH9: Medium | AJ9: https://whc.unesco.org/en/search/?searchterm=Ggantija+UNESCO | AK9: https://whc.unesco.org/en/search/?searchterm=Ggantija+UNESCO | AL9: https://www.si.edu/collection/search?edan_q=Ggantija+UNESCO | AM9: https://whc.unesco.org/en/search/?searchterm=Ggantija+UNESCO | AN9: https://whc.unesco.org/en/search/?searchterm=Ggantija+UNESCO | AO9: 1) Fact base: UNESCO. 2) Translation/text: UNESCO. 3) Images/objects: Smithsonian Open Access. 4) Context/explanation: UNESCO. 5) Geography/maps: UNESCO. Use Suggested_Search_Term inside each portal. | AP9: Mixed: direct portal homepages plus search-result URLs where the portal exposes a public search endpoint.
A10: 9 | B10: BCE_to_1AD | C10: Prehistory / Neolithic | D10: Prehistory and Neolithic traditions | E10: -3600 | F10: -3000 | G10: c. 3600 BCE to 3000 BCE | H10: Hagar Qim | I10: Site | J10: Archaeology | K10: Megaliths | L10: Ritual | M10: Malta | N10: Malta island | O10: Megalithic temple site with carved stone, altars, and figurines. | P10: Often cited in megalithic diffusion theories; worth grounding in island chronology. | Q10: Medium | R10: Not applicable | S10: High | T10: UNESCO | U10: https://whc.unesco.org/ | V10: UNESCO | W10: https://whc.unesco.org/ | X10: Smithsonian Open Access | Y10: https://www.si.edu/openaccess | Z10: UNESCO | AA10: https://whc.unesco.org/ | AB10: UNESCO | AC10: https://whc.unesco.org/ | AD10: Hagar Qim UNESCO | AE10: Best used with Mnajdra and Hypogeum together. | AF10: Temple architecture; figurines | AG10: Medium | AH10: Medium | AJ10: https://whc.unesco.org/en/search/?searchterm=Hagar+Qim+UNESCO | AK10: https://whc.unesco.org/en/search/?searchterm=Hagar+Qim+UNESCO | AL10: https://www.si.edu/collection/search?edan_q=Hagar+Qim+UNESCO | AM10: https://whc.unesco.org/en/search/?searchterm=Hagar+Qim+UNESCO | AN10: https://whc.unesco.org/en/search/?searchterm=Hagar+Qim+UNESCO | AO10: 1) Fact base: UNESCO. 2) Translation/text: UNESCO. 3) Images/objects: Smithsonian Open Access. 4) Context/explanation: UNESCO. 5) Geography/maps: UNESCO. Use Suggested_Search_Term inside each portal. | AP10: Mixed: direct portal homepages plus search-result URLs where the portal exposes a public search endpoint.
A11: 10 | B11: BCE_to_1AD | C11: Prehistory / Neolithic | D11: Prehistory and Neolithic traditions | E11: -3600 | F11: -2500 | G11: c. 3600 BCE to 2500 BCE | H11: Mnajdra | I11: Site | J11: Archaeology | K11: Megaliths | L11: Astronomy | M11: Malta | N11: Malta island | O11: Temple complex often discussed for solar alignment and ritual architecture. | P11: Useful when tracking archaeoastronomy claims against official site interpretation. | Q11: High | R11: Not applicable | S11: High | T11: UNESCO | U11: https://whc.unesco.org/ | V11: UNESCO | W11: https://whc.unesco.org/ | X11: Smithsonian Open Access | Y11: https://www.si.edu/openaccess | Z11: UNESCO | AA11: https://whc.unesco.org/ | AB11: UNESCO | AC11: https://whc.unesco.org/ | AD11: Mnajdra UNESCO | AE11: Separate measured alignments from speculative claims. | AF11: Solar alignment; temple ritual | AG11: Medium | AH11: Medium | AJ11: https://whc.unesco.org/en/search/?searchterm=Mnajdra+UNESCO | AK11: https://whc.unesco.org/en/search/?searchterm=Mnajdra+UNESCO | AL11: https://www.si.edu/collection/search?edan_q=Mnajdra+UNESCO | AM11: https://whc.unesco.org/en/search/?searchterm=Mnajdra+UNESCO | AN11: https://whc.unesco.org/en/search/?searchterm=Mnajdra+UNESCO | AO11: 1) Fact base: UNESCO. 2) Translation/text: UNESCO. 3) Images/objects: Smithsonian Open Access. 4) Context/explanation: UNESCO. 5) Geography/maps: UNESCO. Use Suggested_Search_Term inside each portal. | AP11: Mixed: direct portal homepages plus search-result URLs where the portal exposes a public search endpoint.
A12: 11 | B12: BCE_to_1AD | C12: Prehistory / Neolithic | D12: Prehistory and Neolithic traditions | E12: -4000 | F12: -2500 | G12: c. 4000 BCE to 2500 BCE | H12: Hal Saflieni Hypogeum | I12: Site | J12: Archaeology | K12: Megaliths | L12: Burial | M12: Malta | N12: Malta island | O12: Rock-cut subterranean ritual and burial complex. | P12: Important for underground ritual architecture and acoustics discussions. | Q12: High | R12: Not applicable | S12: Medium | T12: UNESCO | U12: https://whc.unesco.org/ | V12: UNESCO | W12: https://whc.unesco.org/ | X12: Smithsonian Open Access | Y12: https://www.si.edu/openaccess | Z12: UNESCO | AA12: https://whc.unesco.org/ | AB12: UNESCO | AC12: https://whc.unesco.org/ | AD12: Hypogeum UNESCO | AE12: Acoustics claims should be tied to measured studies where possible. | AF12: Underworld symbolism; ritual space | AG12: Medium | AH12: Medium | AJ12: https://whc.unesco.org/en/search/?searchterm=Hypogeum+UNESCO | AK12: https://whc.unesco.org/en/search/?searchterm=Hypogeum+UNESCO | AL12: https://www.si.edu/collection/search?edan_q=Hypogeum+UNESCO | AM12: https://whc.unesco.org/en/search/?searchterm=Hypogeum+UNESCO | AN12: https://whc.unesco.org/en/search/?searchterm=Hypogeum+UNESCO | AO12: 1) Fact base: UNESCO. 2) Translation/text: UNESCO. 3) Images/objects: Smithsonian Open Access. 4) Context/explanation: UNESCO. 5) Geography/maps: UNESCO. Use Suggested_Search_Term inside each portal. | AP12: Mixed: direct portal homepages plus search-result URLs where the portal exposes a public search endpoint.
A13: 12 | B13: BCE_to_1AD | C13: Prehistory / Neolithic | D13: Prehistory and Neolithic traditions | E13: -3000 | F13: -1500 | G13: c. 3000 BCE to 1500 BCE | H13: Stonehenge | I13: Site | J13: Archaeology | K13: Megaliths | L13: Astronomy | M13: United Kingdom | N13: Wessex | O13: Monumental stone circle built in multiple phases. | P13: Central to global megalithic and archaeoastronomy comparisons. | Q13: High | R13: Not applicable | S13: High | T13: UNESCO | U13: https://whc.unesco.org/ | V13: UNESCO | W13: https://whc.unesco.org/ | X13: Smithsonian Open Access | Y13: https://www.si.edu/openaccess | Z13: UNESCO | AA13: https://whc.unesco.org/ | AB13: UNESCO | AC13: https://whc.unesco.org/ | AD13: Stonehenge UNESCO | AE13: Keep phase chronology explicit; many popular claims flatten the sequence. | AF13: Solar/lunar cycles; ritual landscape | AG13: Critical | AH13: High | AJ13: https://whc.unesco.org/en/search/?searchterm=Stonehenge+UNESCO | AK13: https://whc.unesco.org/en/search/?searchterm=Stonehenge+UNESCO | AL13: https://www.si.edu/collection/search?edan_q=Stonehenge+UNESCO | AM13: https://whc.unesco.org/en/search/?searchterm=Stonehenge+UNESCO | AN13: https://whc.unesco.org/en/search/?searchterm=Stonehenge+UNESCO | AO13: 1) Fact base: UNESCO. 2) Translation/text: UNESCO. 3) Images/objects: Smithsonian Open Access. 4) Context/explanation: UNESCO. 5) Geography/maps: UNESCO. Use Suggested_Search_Term inside each portal. | AP13: Mixed: direct portal homepages plus search-result URLs where the portal exposes a public search endpoint.
... A280: 279 | B280: BCE_to_1AD | C280: Africa (outside Egypt) | D280: Saharan prehistoric | E280: -6000 | F280: -1000 | G280: Prehistoric Sahara | H280: Tassili n’Ajjer rock art | I280: Artifact corpus | J280: rock paintings and engravings | K280: ritual imagery | L280: pastoral cosmology | M280: Algeria | N280: Central Sahara | O280: Large corpus of prehistoric rock art documenting fauna, people, ritual postures, and changing ecologies. | P280: Frequently mined by alternative-history media; factual use should stay visual and chronological. | Q280: High | R280: No | S280: Yes | T280: UNESCO | U280: https://whc.unesco.org/ | V280: UNESCO | W280: https://whc.unesco.org/ | X280: UNESCO | Y280: https://whc.unesco.org/ | Z280: UNESCO | AA280: https://whc.unesco.org/ | AB280: UNESCO | AC280: https://whc.unesco.org/ | AD280: Tassili rock art archaeology | AE280: No direct translation issue because it is non-textual. | AF280: Rock art cosmology; sky-beings rhetoric | AG280: High | AH280: Medium | AJ280: https://whc.unesco.org/en/search/?searchterm=Tassili+rock+art+archaeology | AK280: https://whc.unesco.org/en/search/?searchterm=Tassili+rock+art+archaeology | AL280: https://whc.unesco.org/en/search/?searchterm=Tassili+rock+art+archaeology | AM280: https://whc.unesco.org/en/search/?searchterm=Tassili+rock+art+archaeology | AN280: https://whc.unesco.org/en/search/?searchterm=Tassili+rock+art+archaeology | AO280: 1) Fact base: UNESCO. 2) Translation/text: UNESCO. 3) Images/objects: UNESCO. 4) Context/explanation: UNESCO. 5) Geography/maps: UNESCO. Use Suggested_Search_Term inside each portal. | AP280: Mixed: direct portal homepages plus search-result URLs where the portal exposes a public search endpoint.

Sheet Source_Portals
A1: Portal_Name | B1: Coverage | C1: Best_For | D1: Translation_Strength | E1: Image_Strength | F1: Artifact_Record_Strength | G1: Map_Site_Strength | H1: URL
A2: ORACC | B2: Mesopotamian cuneiform texts | C2: annotated transliterations, translations, corpora search | D2: High | E2: Medium | F2: Low | G2: Low | H2: https://oracc.museum.upenn.edu/
A3: ETCSL | B3: Sumerian literary texts | C3: English translations + transliterations of Sumerian literature | D3: High | E3: Low | F3: Low | G3: Low | H3: https://etcsl.orinst.ox.ac.uk/
A4: TLA | B4: Egyptian texts | C4: Egyptian text corpus, transliterations, lemmas | D4: High | E4: Medium | F4: Low | G4: Low | H4: https://thesaurus-linguae-aegyptiae.de/
A5: Papyri.info | B5: Greek, Demotic, Coptic, Egyptian and documentary papyri | C5: texts, metadata, commentary, images | D5: Medium | E5: High | F5: Medium | G5: Low | H5: https://papyri.info/
A6: UCL Digital Egypt | B6: Egyptian civilization overviews | C6: accessible context + object explanations | D6: Medium | E6: Medium | F6: Medium | G6: Low | H6: https://www.ucl.ac.uk/museums-static/digitalegypt/
A7: Sefaria | B7: Hebrew Bible and Jewish literature | C7: Hebrew + English texts | D7: High | E7: Low | F7: Low | G7: Low | H7: https://www.sefaria.org/
A8: Leon Levy Dead Sea Scrolls | B8: Dead Sea Scroll fragments | C8: high-resolution manuscript images + metadata | D8: Medium | E8: High | F8: Low | G8: Low | H8: https://www.deadseascrolls.org.il/
A9: Perseus | B9: Greek and Latin texts | C9: primary texts, translations, references | D9: High | E9: Low | F9: Low | G9: Low | H9: https://www.perseus.tufts.edu/hopper/
A10: Chinese Text Project | B10: Classical Chinese texts | C10: searchable transmitted texts and tools | D10: High | E10: Low | F10: Low | G10: Low | H10: https://ctext.org/
A11: FAMSI | B11: Mesoamerican codices and inscriptions | C11: codex facsimiles, commentary, scripts | D11: Medium | E11: High | F11: Medium | G11: Low | H11: https://www.famsi.org/
A12: Smithsonian Open Access | B12: Global artifacts and images | C12: open-access object images and metadata | D12: Low | E12: High | F12: High | G12: Low | H12: https://www.si.edu/openaccess
... A28: Open Greek and Latin | B28: Greek and Latin corpora | C28: open corpus releases and text infrastructure | D28: High | E28: Low | F28: Low | G28: Low | H28: https://opengreekandlatin.org/

Sheet Story_Arcs
A1: Story_Arc | B1: What_to_trace | C1: Primary_Start_Set | D1: Secondary_Start_Set | E1: Control_Sources | F1: Common_Trap_to_Avoid
A2: Creation from waters / chaos | B2: Primeval waters, mound, spoken creation, divine combat, ordered cosmos | C2: Enuma Elish; Genesis 1; Pyramid Texts; Shabaka Stone; Rigveda hymns; Theogony | D2: Baal Cycle; Shan Hai Jing; Popol Vuh; Viracocha traditions | E2: Official translations + archaeology of cult centers | F2: Do not collapse all watery creation stories into a single direct transmission line.
A3: Flood and world reset | B3: Cause of flood, survivor, vessel, mountain, post-flood law/order | C3: Atrahasis; Gilgamesh XI; Ziusudra; Genesis 6-9; Manu flood | D3: Yu the Great traditions; Viracocha traditions; Deucalion (via Greek sources) | E3: Compare language, cause, and post-flood outcome, not just the fact of water. | F3: Shared motif is not proof of one event by itself.
A4: Divine civilizers / culture heroes | B4: Who teaches agriculture, writing, law, astronomy, city order | C4: Enki and the World Order; Oannes/Apkallu material; Osiris/Ptah; Yu the Great; Quetzalcoatl traditions | D4: Viracocha traditions; Prometheus; culture heroes in oral traditions | E4: Track first secure text/object witness for each figure. | F4: Do not equate figures across cultures too quickly.
A5: Kingship after catastrophe | B5: King lists, dynastic resets, first cities after flood/chaos | C5: Sumerian King List; Abydos King List; Turin Canon; Behistun; Shujing; Mesha Stele | D5: Oracle bones; Ashokan Edicts; Phoenician inscriptions | E5: Use inscriptions to anchor literary king lists. | F5: King lists are ideological, not raw chronology dumps.
A6: Sacred technology / sky knowledge | B6: Calendrics, star lists, devices, alignments, ritual architecture | C6: MUL.APIN; Enuma Anu Enlil; Antikythera Mechanism; Stonehenge; Newgrange; Nabta Playa | D6: Dendera corpus; Mawangdui maps; Maya codices (later witness) | E6: Prioritize what is explicitly documented over what is visually suggestive. | F6: A sophisticated artifact is not evidence of anachronistic civilization by default.
A7: Underworld maps and afterlife routes | B7: Journeys after death, gates, spells, initiatory knowledge | C7: Pyramid Texts; Coffin Texts; Book of the Dead; Amduat; Inanna's Descent; Orphic tablets | D7: Eleusis; Book of Gates; Virgil/late classical comparanda if needed | E7: Keep funerary function in view. | F7: Do not read all underworld texts as literal geography maps.
A8: Creation by speech / naming | B8: Divine utterance, naming, logos, command, songlines | C8: Shabaka Stone; Genesis 1; Vedic hymns | D8: Pyramid Texts; Huainanzi | E8: Read the exact verb and agent doing the creating. | F8: Do not equate metaphorical speech with literal sonic technology without textual support.
A9: Human making / purpose | B9: Clay, blood, labor, sacrifice, failed creations, moral purpose | C9: Enki and Ninmah; Atrahasis; Genesis 2; Purusha Sukta | D9: Popol Vuh (later witness); Aggañña Sutta | E9: Track what humans are for, not only how they are made. | F9: Shared material such as clay does not by itself establish direct borrowing.
A10: Sacred kingship / divine mandate | B10: Why rulers are legitimate, what gods authorize, how order is restored | C10: Narmer Palette; Sumerian King List; Behistun; Ashokan Edicts | D10: Oracle bones; Mesha Stele; Edfu texts | E10: Use inscriptions before later retellings. | F10: Royal ideology is biased evidence, but still first-order evidence.

Sheet Methodology
A1: Methodology / guardrails
A3: 1) Facts vs theory | B3: This workbook inventories primary materials and mainstream archaeological entry points. It does NOT treat cross-cultural similarity as proof. Use the item rows to inspect objects and texts directly before drawing character merges or civilization-transfer theories.
A4: 2) Later witnesses | B4: Some of the most important sources in alternative-history discourse are later than 1 AD (for example Popol Vuh manuscripts, some codices, Viracocha colonial chronicles, some megalithic sites in the Andes, Nan Madol). They are kept in the inventory with Scope_Flag = Later_witness_or_post_1AD_relevance.
A5: 3) Translation status | B5: High = easy public translation access; Partial = fragments, scattered editions, or later witnesses; No = undeciphered or non-text object.
A6: 4) Recommended workflow | B6: Start with Critical + BCE_to_1AD + a single theme (Creation, Flood, Kingship, Astronomy). Build a note-taking table keyed by Record_ID. Then compare only after you have looked at the underlying text/object pages.
A8: Starter research sequence
A9: 1 | B9: Mesopotamia: Sumerian King List, Eridu Genesis, Gilgamesh, Atrahasis, Enki and the World Order, MUL.APIN
A10: 2 | B10: Egypt: Pyramid Texts, Coffin Texts, Book of the Dead, Shabaka Stone, Edfu texts, Abydos King List
A11: 3 | B11: Levant / Hebrew: Genesis 1-11, Dead Sea Scrolls, 1 Enoch, Jubilees, Ugarit Baal Cycle, Mesha Stele
A12: 4 | B12: South Asia: Rigveda, Satapatha Brahmana, Manu flood, early Upanishads, Ashokan Edicts, Indus seal corpus
A13: 5 | B13: China: Oracle bones, Shang/Zhou bronzes, Shan Hai Jing, Yijing, Mawangdui maps, Yu the Great traditions
A14: 6 | B14: Mesoamerica / Andes: San Bartolo murals, Izapa, El Mirador, Caral, Chavin, Nazca; then later witnesses like Popol Vuh and Viracocha traditions

Sheet Belief_Themes_v2
A1: Theme | B1: What_to_trace | C1: Anchor_cultures | D1: Must_start_with | E1: Secondary_expansion | F1: Control_question | G1: Guardrail
A2: Primeval waters / chaos | B2: Nun, Apsu, Yam, undifferentiated void, cosmic sea | C2: Egypt; Mesopotamia; Levant; India; Greece | D2: Pyramid Texts; Enuma Elish; Genesis 1; Nasadiya Sukta | E2: Shan Hai Jing; Popol Vuh; Viracocha later witnesses | F2: Is water the origin, a battle context, or ritual symbol? | G2: Shared watery imagery is not proof of a single transmission path.
A3: Creation by speech / mind | B3: Heart, tongue, logos, utterance, naming, song | C3: Egypt; Hebrew; India; China | D3: Shabaka Stone; Genesis 1; Vedic hymns | E3: Dreaming songlines; later philosophical traditions | F3: Does speech create substance, order, or law? | G3: Do not flatten priestly theology, poetry, and oral law into one genre.
A4: Creation of humans | B4: Clay, blood, sacrifice, fashioning, failed creations | C4: Mesopotamia; Hebrew; India; Mesoamerica | D4: Enki and Ninmah; Atrahasis; Genesis 2 | E4: Popol Vuh later witness; Aggañña Sutta | F4: What are humans made for in each system? | G4: Function and ontology matter more than surface material similarity.
A5: Flood / catastrophe reset | B5: Cause, survivor, vessel/enclosure, mountain, covenant/order | C5: Mesopotamia; Hebrew; India; Iran; Greece | D5: Atrahasis; Gilgamesh XI; Genesis 6-9; Manu flood; Yima Vara | E5: Viracocha later witness; Deucalion; Yu traditions | F5: Is the reset moral, climatic, political, or cosmic? | G5: A shared flood motif alone does not prove one global event.
A6: Divine civilizers | B6: Teachers of writing, law, agriculture, architecture, kingship | C6: Mesopotamia; Egypt; China; Mesoamerica; Andes | D6: Enki and the World Order; Apkallu; Edfu texts; Shujing/Yu | E6: Quetzalcoatl and Viracocha later witnesses | F6: What specific skill or order does the figure introduce? | G6: Do not merge figures before listing their functions side by side.
A7: World ages / decline | B7: Golden age, bronze age, yugas, moral degeneration | C7: Greece; India; Iran; Jewish apocalyptic | D7: Works and Days; Mahabharata yuga material; Gathas/Yima | E7: Daniel; 1 Enoch | F7: Is decline moral, technological, genealogical, or cosmic? | G7: Separate cyclical ages from one-time catastrophe narratives.
A8: Sacred kingship | B8: Divine legitimation, temple-building, victory, law | C8: Egypt; Mesopotamia; Levant; Persia; India | D8: Narmer Palette; king lists; Mesha Stele; Behistun; Ashokan edicts | E8: Oracle bones; Zhou bronzes | F8: How is kingship tied to divine order? | G8: Royal propaganda is evidence, but not neutral evidence.
A9: Astronomy / omen systems | B9: Celestial regularity, prophecy, calendar, eclipse, solstice | C9: Mesopotamia; Egypt; China; Maya; Britain | D9: Enuma Anu Enlil; MUL.APIN; Oracle bones; Stonehenge | E9: Dresden Codex later witness; Newgrange; Nabta Playa | F9: Is the evidence predictive, calendrical, or symbolic? | G9: Do not turn every alignment into a precision observatory claim.

Sheet Character_Parallels
A1: Parallel_Group | B1: Motif | C1: Figure | D1: Culture_Tradition | E1: Region | F1: Date_Context | G1: Role_Type | H1: Core_Function | I1: Closest_Parallels | J1: Main_Texts_or_Witnesses | K1: Main_Sites_or_Objects | L1: Identity_Status | M1: Comparison_Rationale | N1: Best_Fact_Portal | O1: Best_Fact_URL | P1: Best_Translation_Portal | Q1: Best_Translation_URL | R1: Best_Image_or_Object_Portal | S1: Best_Image_or_Object_URL | T1: Master_Inventory_Match | U1: Research_Note
A2: Flood survivor / preserver | B2: Global deluge, preservation of life | C2: Ziusudra | D2: Sumerian | E2: Mesopotamia | F2: 3rd–2nd millennium BCE witnesses | G2: Flood survivor | H2: Chosen survivor of divine flood | I2: Utnapishtim; Atrahasis; Noah; Manu | J2: Eridu Genesis / Sumerian flood tradition | K2: Eridu; Sumerian tablets | L2: Possible same memory stream | M2: Shared pattern of warning, vessel, survival, sacrifice, post-flood continuity | N2: ETCSL | O2: https://etcsl.orinst.ox.ac.uk/ | P2: ETCSL | Q2: https://etcsl.orinst.ox.ac.uk/cgi-bin/etcsl.cgi?text=all | R2: British Museum Collection | S2: https://www.britishmuseum.org/collection | T2: Ziusudra Flood Story | U2: Best starting point for early Sumerian flood memory.
A3: Flood survivor / preserver | B3: Global deluge, preservation of life | C3: Atrahasis | D3: Akkadian / Babylonian | E3: Mesopotamia | F3: 2nd millennium BCE witnesses | G3: Flood survivor | H3: Human preserver warned by deity | I3: Ziusudra; Utnapishtim; Noah; Manu | J3: Atrahasis Epic | K3: Mesopotamian tablet corpus | L3: Possible same memory stream | M3: Shared boat-building and divine-warning structure with other flood heroes | N3: ORACC | O3: https://oracc.museum.upenn.edu/ | P3: ORACC | Q3: https://oracc.museum.upenn.edu/ | R3: British Museum Collection | S3: https://www.britishmuseum.org/collection | T3: Atrahasis | U3: Use for detailed Akkadian flood formulation.
A4: Flood survivor / preserver | B4: Global deluge, preservation of life | C4: Utnapishtim | D4: Akkadian | E4: Mesopotamia | F4: 1st millennium BCE standard Babylonian witness | G4: Flood survivor | H4: Immortal survivor in epic frame | I4: Ziusudra; Atrahasis; Noah; Manu | J4: Epic of Gilgamesh Tablet XI | K4: Nineveh / Ashurbanipal Library | L4: Possible same memory stream | M4: Narrative overlaps strongly with biblical and earlier Mesopotamian flood structures | N4: ORACC | O4: https://oracc.museum.upenn.edu/ | P4: ORACC | Q4: https://oracc.museum.upenn.edu/ | R4: British Museum Collection | S4: https://www.britishmuseum.org/collection | U4: Best known flood witness in later Akkadian literature.
A5: Flood survivor / preserver | B5: Global deluge, preservation of life | C5: Noah | D5: Hebrew Bible / Second Temple | E5: Levant / Israel / Phoenicia | F5: Late 1st millennium BCE textual witnesses | G5: Flood survivor | H5: Chosen righteous preserver | I5: Ziusudra; Atrahasis; Utnapishtim; Manu | J5: Genesis 6–9; later Second Temple expansions | K5: Qumran / Dead Sea Scroll context | L5: Possible same memory stream | M5: Preservation of family/animals and covenant motif parallel Mesopotamian flood cycles | N5: Sefaria | O5: https://www.sefaria.org/Genesis.6 | P5: Sefaria | Q5: https://www.sefaria.org/Genesis.6 | R5: Dead Sea Scrolls Digital Library | S5: https://www.deadseascrolls.org.il/ | U5: Use DSS for manuscript witnesses and Sefaria for readable translation.
A6: Flood survivor / preserver | B6: Flood / renewal | C6: Manu | D6: Vedic / early Hindu | E6: South Asia | F6: Late BCE textual witness to older oral tradition | G6: Flood survivor / lawgiver | H6: Preserver through flood and renewer of order | I6: Noah; Ziusudra; Utnapishtim; Deucalion | J6: Satapatha Brahmana flood episode | K6: South Asian manuscript tradition | L6: Structural parallel | M6: Warning + preserved seed of order is the main comparison point | N6: Sacred Texts / translated editions | O6: https://www.sacred-texts.com/hin/ | P6: Sacred Texts / translated editions | Q6: https://www.sacred-texts.com/hin/ | R6: British Library / museum collections | S6: https://www.bl.uk/collection-guides | T6: Manu flood tradition; Śatapatha Brāhmaṇa flood of Manu; Chu Silk Manuscript | U6: Treat as an Indian flood-renewal analogue, not automatic identity.
A7: Flood survivor / preserver | B7: Flood / renewal | C7: Deucalion | D7: Greek | E7: Aegean / Greece / Italy | F7: Late BCE/early CE literary witnesses to older tradition | G7: Flood survivor | H7: Greek deluge survivor | I7: Noah; Utnapishtim; Manu | J7: Apollodorus / Ovid / Greek myth tradition | K7: Greek literary corpus | L7: Structural parallel | M7: Greek version preserves ark-like survival and repopulation theme | N7: Perseus | O7: https://www.perseus.tufts.edu/hopper/ | P7: Perseus | Q7: https://www.perseus.tufts.edu/hopper/ | R7: Perseus Art & Archaeology | S7: https://perseus.pubpub.org/ | U7: Use as Greek comparative witness rather than primary Bronze Age record.
A8: Flood survivor / preserver | B8: Cataclysm shelter / preservation | C8: Yima | D8: Avestan / Iranian | E8: Iran / Central Asia | F8: Late BCE witness to older Iranian tradition | G8: Cataclysm preserver | H8: Builds enclosure to preserve life against world-destroying winter | I8: Manu; Noah; Utnapishtim | J8: Vendidad / Avestan tradition | K8: Iranian manuscript tradition | L8: Structural parallel | M8: Not a flood story in strict sense, but a preservation-through-cataclysm parallel | N8: Sacred Texts / translated Avesta | O8: https://www.sacred-texts.com/zor/avesta/ | P8: Sacred Texts / translated Avesta | Q8: https://www.sacred-texts.com/zor/avesta/ | R8: British Library / museum collections | S8: https://www.bl.uk/collection-guides | T8: Yima and the Vara | U8: Good for broader cataclysm-memory map.
A9: Flood survivor / preserver | B9: Hellenistic bridge figure | C9: Xisuthros | D9: Berossus / Hellenistic Mesopotamian | E9: Mesopotamia | F9: Hellenistic witness preserving older Mesopotamian material | G9: Flood survivor | H9: Greek rendering of Mesopotamian flood hero | I9: Ziusudra; Utnapishtim | J9: Berossus fragments | K9: Classical quotations corpus | L9: Likely same memory stream | M9: Helpful bridge between Mesopotamian and Greek reception history | N9: Perseus | O9: https://www.perseus.tufts.edu/hopper/ | P9: Perseus | Q9: https://www.perseus.tufts.edu/hopper/ | R9: British Museum Collection | S9: https://www.britishmuseum.org/collection | U9: Useful reception-history comparator.
A10: Civilizer / wisdom bearer | B10: Order, crafts, freshwater wisdom | C10: Enki | D10: Sumerian | E10: Mesopotamia | F10: 3rd–2nd millennium BCE witnesses | G10: God / civilizer | H10: Assigns order, crafts, wisdom, waters | I10: Oannes; Thoth; Ptah; Prometheus; Viracocha | J10: Enki and the World Order; Enki myths | K10: Eridu; Sumerian tablets | L10: Structural parallel | M10: Civilizing, technical, and culture-ordering functions recur widely | N10: ETCSL | O10: https://etcsl.orinst.ox.ac.uk/ | P10: ETCSL | Q10: https://etcsl.orinst.ox.ac.uk/cgi-bin/etcsl.cgi?text=all | R10: British Museum Collection | S10: https://www.britishmuseum.org/collection | T10: Enki and Ninhursag; Enki and the World Order; Enki and Ninhursag | U10: Central figure for your civilizer-god thread.
A11: Civilizer / wisdom bearer | B11: Sea-borne teacher of civilization | C11: Oannes | D11: Mesopotamian / Hellenistic witness | E11: Mesopotamia | F11: Hellenistic witness to older Mesopotamian tradition | G11: Culture hero | H11: Teacher of writing, arts, law, agriculture | I11: Enki; Apkallu; Thoth; Quetzalcoatl | J11: Berossus tradition | K11: Babylonia in classical witness | L11: Structural parallel | M11: Strong “teacher from the waters” pattern | N11: Perseus | O11: https://www.perseus.tufts.edu/hopper/ | P11: Perseus | Q11: https://www.perseus.tufts.edu/hopper/ | R11: British Museum Collection | S11: https://www.britishmuseum.org/collection | U11: Treat as later literary witness to older Mesopotamian lore.
A12: Civilizer / wisdom bearer | B12: Primeval sages and culture transmission | C12: Apkallu | D12: Mesopotamian | E12: Mesopotamia | F12: 1st millennium BCE witness to earlier traditions | G12: Sage / demi-god | H12: Transmit rites, wisdom, technical knowledge | I12: Oannes; Watchers; Seven Sages traditions | J12: Apkallu texts / protective ritual corpus | K12: Assyrian-Babylonian reliefs and texts | L12: Structural parallel | M12: Hybrid sage figures used to explain transmission of knowledge | N12: ORACC | O12: https://oracc.museum.upenn.edu/ | P12: ORACC | Q12: https://oracc.museum.upenn.edu/ | R12: British Museum Collection | S12: https://www.britishmuseum.org/collection | T12: Apkallu / antediluvian sages traditions | U12: Important for “civilization was taught” motif.
A13: Civilizer / wisdom bearer | B13: Writing, measurement, sacred knowledge | C13: Thoth | D13: Egyptian | E13: Egypt | F13: 3rd–1st millennium BCE witnesses | G13: God / scribe | H13: Writing, wisdom, reckoning, divine speech | I13: Enki; Oannes; Hermes; Prometheus | J13: Temple inscriptions; funerary texts; wisdom texts | K13: Hermopolis / temple corpus | L13: Structural parallel | M13: Scribal wisdom and cosmic ordering overlap with Enki-type functions | N13: TLA | O13: https://thesaurus-linguae-aegyptiae.de/home | P13: TLA | Q13: https://thesaurus-linguae-aegyptiae.de/home | R13: British Museum Collection | S13: https://www.britishmuseum.org/collection | U13: Use TLA for texts and museum collections for ibis/baboon imagery.
A14: Civilizer / wisdom bearer | B14: Crafts, divine speech, world ordering | C14: Ptah | D14: Egyptian | E14: Egypt | F14: Old Kingdom onward | G14: Creator / civilizer | H14: Creates by heart and tongue; patron of craft | I14: Enki; Logos traditions | J14: Memphite Theology / Shabaka Stone | K14: Memphis / Shabaka Stone | L14: Structural parallel | M14: Speech-creation plus craft patronage makes Ptah a major comparison node | N14: TLA | O14: https://thesaurus-linguae-aegyptiae.de/home | P14: TLA | Q14: https://thesaurus-linguae-aegyptiae.de/home | R14: British Museum Collection | S14: https://www.britishmuseum.org/collection | U14: Strong for speech-as-technology thread.
A15: Civilizer / wisdom bearer | B15: Kingship, agriculture, restoration | C15: Osiris | D15: Egyptian | E15: Egypt | F15: Old Kingdom onward | G15: Divine king / civilizer | H15: Brings ordered kingship and agriculture, dies and returns | I15: Viracocha; Quetzalcoatl (broadly symbolic); Dumuzi | J15: Pyramid Texts; Coffin Texts; temple material | K15: Abydos; temple corpus | L15: Structural parallel | M15: More resurrection-kingship than direct same-person parallel | N15: TLA | O15: https://thesaurus-linguae-aegyptiae.de/home | P15: TLA | Q15: https://thesaurus-linguae-aegyptiae.de/home | R15: British Museum Collection | S15: https://www.britishmuseum.org/collection | T15: Osiris Myth Cycle | U15: Good for sacral kingship and afterlife order.
A16: Civilizer / wisdom bearer | B16: Fire / craft / stolen knowledge | C16: Prometheus | D16: Greek | E16: Aegean / Greece / Italy | F16: Archaic Greek textual witnesses | G16: Culture hero | H16: Brings fire and technical capacity to humankind | I16: Enki; Oannes; Quetzalcoatl | J16: Hesiod; later Greek drama | K16: Greek literary corpus | L16: Structural parallel | M16: Knowledge-gift motif aligns, but rebellion motif is distinct | N16: Perseus | O16: https://www.perseus.tufts.edu/hopper/ | P16: Perseus | Q16: https://www.perseus.tufts.edu/hopper/ | R16: Perseus Art & Archaeology | S16: https://perseus.pubpub.org/ | U16: Good for technology gift motif.
A17: Civilizer / wisdom bearer | B17: Feathered-serpent teacher | C17: Quetzalcoatl | D17: Mesoamerican | E17: Mesoamerica | F17: Late pre-Columbian and early colonial witnesses to older traditions | G17: Culture hero / god | H17: Order, knowledge, wind, priesthood, calendar associations | I17: Viracocha; Oannes; Thoth | J17: Codices and Nahua traditions | K17: Central Mexican codices and sites | L17: Structural parallel | M17: Civilizer-teacher profile is the main basis of comparison | N17: FAMSI | O17: https://www.famsi.org/mayawriting/codices/ | P17: FAMSI | Q17: https://www.famsi.org/mayawriting/codices/ | R17: Smithsonian Open Access | S17: https://www.si.edu/openaccess | T17: Quetzalcoatl / Kukulkan traditions | U17: Later witness status should stay flagged.
A18: Civilizer / wisdom bearer | B18: Creator / wanderer / teacher | C18: Viracocha | D18: Andean | E18: Andes / South America | F18: Colonial textual witnesses to older Andean tradition | G18: Culture hero / creator | H18: Creates order, travels, instructs, departs | I18: Quetzalcoatl; Oannes; Enki | J18: Colonial chronicles preserving Inca/Andean traditions | K18: Lake Titicaca / Tiwanaku orbit | L18: Structural parallel | M18: Teacher-wanderer motif drives the comparison, not proven historical identity | N18: Internet Archive / translated chronicles | O18: https://archive.org/ | P18: Internet Archive / translated chronicles | Q18: https://archive.org/ | R18: Smithsonian Open Access | S18: https://www.si.edu/openaccess | T18: Viracocha traditions; Viracocha origin traditions | U18: Use with heavy witness-date caution.
A19: Civilizer / wisdom bearer | B19: Culture founder, writing, marriage order | C19: Fu Xi | D19: Chinese | E19: China | F19: Classical textual witnesses | G19: Culture hero | H19: Introduces trigrams, order, hunting/fishing, social rules | I19: Thoth; Oannes; Quetzalcoatl | J19: Classical Chinese texts | K19: Chinese textual corpus | L19: Structural parallel | M19: Founding-knowledge pattern is the main comparison point | N19: Chinese Text Project | O19: https://ctext.org/ | P19: Chinese Text Project | Q19: https://ctext.org/ | R19: Smithsonian Open Access | S19: https://www.si.edu/openaccess | U19: Strong for East Asian culture-founder strand.
A20: Civilizer / wisdom bearer | B20: Founding emperor, arts and order | C20: Huangdi | D20: Chinese | E20: China | F20: Classical textual witnesses | G20: Culture hero / sacral king | H20: Medicine, governance, order, cosmic legitimacy | I20: Osiris; Menes; Quetzalcoatl | J20: Classical Chinese texts / early histories | K20: Chinese historical-myth corpus | L20: Structural parallel | M20: Blend of mythic founder and civilizing ruler | N20: Chinese Text Project | O20: https://ctext.org/ | P20: Chinese Text Project | Q20: https://ctext.org/ | R20: Smithsonian Open Access | S20: https://www.si.edu/openaccess | U20: Useful founder-king parallel.
A21: Civilizer / wisdom bearer | B21: Law, kingship, agriculture | C21: Yu the Great | D21: Chinese | E21: China | F21: Late BCE/early imperial witnesses to older tradition | G21: Flood tamer / founder | H21: Tames waters, founds order | I21: Manu; Noah (cataclysm response); Menes | J21: Shujing; Shiji tradition | K21: Chinese flood-control legend sphere | L21: Structural parallel | M21: Closer to post-flood organizer than ark survivor | N21: Chinese Text Project | O21: https://ctext.org/ | P21: Chinese Text Project | Q21: https://ctext.org/ | R21: Smithsonian Open Access | S21: https://www.si.edu/openaccess | T21: Yu the Great and flood-control tradition | U21: Key Chinese catastrophe-order figure.
A22: Creator / primeval order | B22: Primeval waters and generation | C22: Apsu | D22: Mesopotamian | E22: Mesopotamia | F22: 1st millennium BCE standard Babylonian witness | G22: Primeval being | H22: Freshwater deep / primordial source | I22: Nun; primeval waters motifs globally | J22: Enuma Elish | K22: Babylonian creation corpus | L22: Structural parallel | M22: One of the clearest primeval-water witnesses | N22: ORACC | O22: https://oracc.museum.upenn.edu/ | P22: ORACC | Q22: https://oracc.museum.upenn.edu/ | R22: British Museum Collection | S22: https://www.britishmuseum.org/collection | U22: Use with Tiamat as pair.
A23: Creator / primeval order | B23: Primeval saltwater chaos | C23: Tiamat | D23: Mesopotamian | E23: Mesopotamia | F23: 1st millennium BCE standard Babylonian witness | G23: Primeval being / chaos sea | H23: Saltwater chaos prior to ordered cosmos | I23: Chaos; Nun; Tehom analog discussions | J23: Enuma Elish | K23: Babylonian creation corpus | L23: Structural parallel | M23: Main comparison point is chaos-sea before ordering | N23: ORACC | O23: https://oracc.museum.upenn.edu/ | P23: ORACC | Q23: https://oracc.museum.upenn.edu/ | R23: British Museum Collection | S23: https://www.britishmuseum.org/collection | U23: Often important in biblical-comparative work.
A24: Creator / primeval order | B24: Order from chaos, cosmic kingship | C24: Marduk | D24: Babylonian | E24: Mesopotamia | F24: 1st millennium BCE witness preserving earlier material | G24: Creator / warrior king | H24: Defeats chaos and structures cosmos | I24: Zeus; Indra; storm-god orderers | J24: Enuma Elish | K24: Babylonian temple-literary corpus | L24: Structural parallel | M24: Victory-over-chaos pattern recurs widely | N24: ORACC | O24: https://oracc.museum.upenn.edu/ | P24: ORACC | Q24: https://oracc.museum.upenn.edu/ | R24: British Museum Collection | S24: https://www.britishmuseum.org/collection | U24: Useful for order-from-chaos comparisons.
A25: Creator / primeval order | B25: Self-generation from primeval waters | C25: Atum | D25: Egyptian | E25: Egypt | F25: Old Kingdom onward | G25: Creator god | H25: Self-generated source of first emanations | I25: Prajapati; Chaos-to-order models | J25: Pyramid Texts; Heliopolitan theology | K25: Heliopolis / Egyptian theological corpus | L25: Structural parallel | M25: Creator-by-emanation theme contrasts with combat creation models | N25: TLA | O25: https://thesaurus-linguae-aegyptiae.de/home | P25: TLA | Q25: https://thesaurus-linguae-aegyptiae.de/home | R25: British Museum Collection | S25: https://www.britishmuseum.org/collection | T25: Pyramid Texts on Atum and the primeval mound | U25: Important non-combat creation pattern.
A26: Creator / primeval order | B26: Primeval waters | C26: Nun | D26: Egyptian | E26: Egypt | F26: Old Kingdom onward | G26: Primeval state | H26: Watery undifferentiated source | I26: Apsu; Tiamat; chaotic waters motifs | J26: Pyramid Texts / Egyptian cosmogonies | K26: Egyptian theological corpus | L26: Structural parallel | M26: Core water-before-creation theme | N26: TLA | O26: https://thesaurus-linguae-aegyptiae.de/home | P26: TLA | Q26: https://thesaurus-linguae-aegyptiae.de/home | R26: British Museum Collection | S26: https://www.britishmuseum.org/collection | U26: Pair with Atum for Egyptian creation stack.
A27: Creator / primeval order | B27: Creation by heart and tongue | C27: Ptah | D27: Egyptian | E27: Egypt | F27: Old Kingdom onward | G27: Creator god | H27: Brings world by thought and speech | I27: Logos; Brahman; word-creation motifs | J27: Memphite Theology / Shabaka Stone | K27: Memphis | L27: Structural parallel | M27: Speech-creation and conceptual creation make Ptah key for consciousness frameworks | N27: TLA | O27: https://thesaurus-linguae-aegyptiae.de/home | P27: TLA | Q27: https://thesaurus-linguae-aegyptiae.de/home | R27: British Museum Collection | S27: https://www.britishmuseum.org/collection | U27: One of the strongest “thought/speech creation” witnesses.
A28: Creator / primeval order | B28: Cosmic sacrifice | C28: Purusha | D28: Vedic | E28: South Asia | F28: Late BCE written witness to older oral layer | G28: Cosmic being | H28: World and social order emerge from sacrificed cosmic person | I28: Ymir; primordial being motifs | J28: Rigveda 10.90 | K28: Vedic textual corpus | L28: Structural parallel | M28: Creation-through-dismemberment is comparative anchor | N28: Sacred Texts / translated Vedic corpus | O28: https://www.sacred-texts.com/hin/rigveda/ | P28: Sacred Texts / translated Vedic corpus | Q28: https://www.sacred-texts.com/hin/rigveda/ | R28: British Library / museum collections | S28: https://www.bl.uk/collection-guides | U28: Strong for body-to-cosmos motif.
A29: Creator / primeval order | B29: Questioning hymn of origins | C29: Nasadiya hymn | D29: Vedic | E29: South Asia | F29: Late BCE written witness to older oral layer | G29: Creation text | H29: Speculative hymn on pre-creation state | I29: Chaos/void creation traditions globally | J29: Rigveda 10.129 | K29: Vedic textual corpus | L29: Structural parallel | M29: Useful because it preserves uncertainty, not just doctrinal certainty | N29: Sacred Texts / translated Vedic corpus | O29: https://www.sacred-texts.com/hin/rigveda/ | P29: Sacred Texts / translated Vedic corpus | Q29: https://www.sacred-texts.com/hin/rigveda/ | R29: British Library / museum collections | S29: https://www.bl.uk/collection-guides | T29: Nasadiya Sukta (Rigveda 10.129) | U29: A strong control against over-forced parallels.
A30: Creator / primeval order | B30: Chaos, earth, sky succession | C30: Chaos / Gaia / Ouranos | D30: Greek | E30: Aegean / Greece / Italy | F30: Archaic Greek witness | G30: Primeval beings | H30: Initial generation of cosmos in genealogical form | I30: Tiamat/Apsu; Atum/Nun (structural only) | J30: Hesiod Theogony | K30: Greek textual corpus | L30: Structural parallel | M30: Good for genealogy-based creation comparison | N30: Perseus | O30: https://www.perseus.tufts.edu/hopper/ | P30: Perseus | Q30: https://www.perseus.tufts.edu/hopper/ | R30: Perseus Art & Archaeology | S30: https://perseus.pubpub.org/ | U30: Greek baseline for creation genealogy.
